---
id: "879289"
title: "Exception Handling In Python"
slug: "exception-handling-in-python"
difficulty: "Easy"
companyTags: []
tags: []
---

Exception Handling In Python
==========================

Slug: exception-handling-in-python
Difficulty: Easy
Id: 879289

## Summary
This problem is about handling exceptions in Python, which is a fundamental concept for writing robust and error-free code. The key concepts involved are try-except blocks, types of exceptions, and how to handle them effectively.

## Detailed Explanation
The goal is to write a program that can catch and handle exceptions. For instance, if we have a function that divides two numbers, we need to make sure it doesn't crash when the divisor is zero. We can use try-except blocks to achieve this.

Here's an example:
```python
try:
    x = 5 / 0
except ZeroDivisionError:
    print("Cannot divide by zero!")
```
In this example, the `try` block contains a statement that may raise an exception (in this case, dividing by zero). The `except` block is used to catch and handle this exception. If the division operation raises a `ZeroDivisionError`, it will be caught by the `except` block, and we can print an error message.

Here's a step-by-step breakdown of the solution:

1. Identify the potential points where exceptions might occur in your code.
2. Wrap these sections in try-except blocks to catch any exceptions that might be raised.
3. In the except block, handle the exception by printing an error message or taking some other action.

Time complexity: O(1) (since we're just catching and handling exceptions)
Space complexity: O(1) (we're not using any extra space)

## Optimized Solutions

### Python
```python
def divide(a, b):
    try:
        result = a / b
        return result
    except ZeroDivisionError:
        print("Cannot divide by zero!")
```
This solution is straightforward and easy to understand. It uses a try-except block to catch the `ZeroDivisionError` exception and prints an error message if the division operation fails.

### Java
```java
public class ExceptionHandling {
    public static double divide(double a, double b) {
        try {
            return a / b;
        } catch (ArithmeticException e) {
            System.out.println("Cannot divide by zero!");
        }
    }
}
```
This solution is similar to the Python one. It uses a try-catch block to catch the `ArithmeticException` exception and prints an error message if the division operation fails.

### C++
```cpp
#include <iostream>
using namespace std;

double divide(double a, double b) {
    try {
        return a / b;
    } catch (const runtime_error& e) {
        cout << "Cannot divide by zero!" << endl;
    }
}
```
This solution is similar to the Python and Java ones. It uses a try-catch block to catch the `runtime_error` exception and prints an error message if the division operation fails.

### JavaScript
```javascript
function divide(a, b) {
    try {
        return a / b;
    } catch (error) {
        console.log("Cannot divide by zero!");
    }
}
```
This solution is similar to the Python one. It uses a try-catch block to catch any exception that might be raised and prints an error message if the division operation fails.

Note: The `try`-`catch` syntax in JavaScript is slightly different from other languages, but the concept remains the same â€“ catch and handle exceptions!